promise.then(f1).catch(f2);

promise.then(f1, f2);

// первый пример обрабатывает потенциальный error, второй - нет